<?xml version="1.0" ?>
<robot name="turtlebot3_waffle" xmlns:xacro="http://ros.org/wiki/xacro">
  <xacro:include filename="$(find robodog1)/urdf/rbd_common_properties.xacro"/>
  <xacro:include filename="$(find robodog1)/urdf/rbd_turtlebot3_waffle.gazebo2.xacro"/>

  <xacro:property name="r200_cam_rgb_px" value="0.005"/>
  <xacro:property name="r200_cam_rgb_py" value="0.018"/>
  <xacro:property name="r200_cam_rgb_pz" value="0.013"/>
  <xacro:property name="r200_cam_depth_offset" value="0.01"/>

  <link name="base_footprint"/>

  <joint name="base_joint" type="fixed">
    <parent link="base_footprint"/>
    <child link="base_link" />
    <origin xyz="0 0 0.010" rpy="0 0 0"/>
  </joint>
    
  <link name="base_link">
    <visual>
        <geometry>
            <box size="0.40 0.32 0.05"/>
            <!--<box size="0.40 0.32 0.10"/>-->
        </geometry>
        <material name="grey">
            <color rgba="1 0.0 0.0 1"/>
        </material>
    </visual>
    <collision>
      <geometry>
        <box size="0.42 0.34 0.11"/>
        <!--
        <box size="0.41 0.33 0.11"/>
        -->
      </geometry>
    </collision>
    <inertial>
        <mass value="1.0"/>
        <inertia ixx="0.015" ixy="0" ixz="0" iyy="0.0375" iyz="0.0" izz="0.0375"/>
    </inertial>
  </link>

<!-- rodas frente -->

  <!-- roda frente esquerda -->

  <joint name="wheel_left_joint_frente" type="continuous">
    <parent link="base_link"/>
    <child link="wheel_left_link_frente"/>
    <origin xyz="0.115 0.20 -0.08" rpy="-1.57 0 0"/>
    <axis xyz="0 0 1"/>
  </joint>

  <link name="wheel_left_link_frente">
    <visual>
      <geometry>
        <cylinder radius="0.05" length="0.042"/>
      </geometry>
      <material name="blue">
        <color rgba="0.0 0.0 0.0 1"/>
      </material>
    </visual>
    <collision>
      <geometry>
        <cylinder radius="0.06" length="0.052"/>
      </geometry>
    </collision>
    <inertial>
      <mass value="0.1"/>
      <inertia ixx="5.1458e-5" ixy="0" ixz="0" iyy="5.1458e-5" iyz="0.0" izz="6.125e-5"/>        
    </inertial>
  </link>

  <!-- roda frente direita -->

  <joint name="wheel_right_joint_frente" type="continuous">
    <parent link="base_link"/>
    <child link="wheel_right_link_frente"/>
    <origin xyz="0.115 -0.20 -0.08" rpy="-1.57 0 0"/>
    <axis xyz="0 0 1"/>
  </joint>

  <link name="wheel_right_link_frente">
    <visual>
      <geometry>
        <cylinder radius="0.05" length="0.042"/>
      </geometry>
      <material name="blue">
        <color rgba="0.0 0.0 0.0 1"/>
      </material>
    </visual>
    <collision>
      <geometry>
          <cylinder radius="0.06" length="0.052"/>
      </geometry>
    </collision>
    <inertial>
      <mass value="0.1"/>
      <inertia ixx="5.1458e-5" ixy="0" ixz="0" iyy="5.1458e-5" iyz="0.0" izz="6.125e-5"/>        
    </inertial>
  </link>

  <!-- rodas tras -->

  <joint name="wheel_left_joint" type="continuous">
    <parent link="base_link"/>
    <child link="wheel_left_link"/>
    <origin xyz="-0.115 0.20 -0.08" rpy="-1.57 0 0"/>
    <axis xyz="0 0 1"/>
  </joint>

  <link name="wheel_left_link">
    <visual>
        <geometry>
            <cylinder radius="0.05" length="0.042"/>
        </geometry>
        <material name="blue">
            <color rgba="0.0 0.0 0.0 1"/>
        </material>
    </visual>
    <collision>
        <geometry>
            <cylinder radius="0.06" length="0.052"/>
        </geometry>
    </collision>
    <inertial>
        <mass value="0.1"/>
        <inertia ixx="5.1458e-5" ixy="0" ixz="0" iyy="5.1458e-5" iyz="0.0" izz="6.125e-5"/>        
    </inertial>
  </link>

  <joint name="wheel_right_joint" type="continuous">
    <parent link="base_link"/>
    <child link="wheel_right_link"/>
    <origin xyz="-0.115 -0.20 -0.08" rpy="-1.57 0 0"/>
    <axis xyz="0 0 1"/>
  </joint>

  <link name="wheel_right_link">
    <visual>
        <geometry>
            <cylinder radius="0.05" length="0.042"/>
        </geometry>
        <material name="blue">
            <color rgba="0.0 0.0 0.0 1"/>
        </material>
    </visual>
    <collision>
        <geometry>
            <cylinder radius="0.06" length="0.052"/>
        </geometry>
    </collision>
    <inertial>
        <mass value="0.1"/>
        <inertia ixx="5.1458e-5" ixy="0" ixz="0" iyy="5.1458e-5" iyz="0.0" izz="6.125e-5"/>        
    </inertial>
  </link>

  <!-- rodas fim -->
  <!--
      <joint name="caster_back_right_joint" type="fixed">
        <parent link="base_link"/>
        <child link="caster_back_right_link"/>
        <origin xyz="-0.177 -0.064 -0.004" rpy="-1.57 0 0"/>
      </joint>

      <link name="caster_back_right_link">
            <collision>
              <origin xyz="0 0.001 0" rpy="0 0 0"/>
              <geometry>
                <box size="0.030 0.009 0.020"/>
              </geometry>
            </collision>

            <inertial>
              <origin xyz="0 0 0" />
              <mass value="0.005" />
              <inertia ixx="0.001" ixy="0.0" ixz="0.0"
                      iyy="0.001" iyz="0.0"
                      izz="0.001" />
            </inertial>
      </link>

      <joint name="caster_back_left_joint" type="fixed">
        <parent link="base_link"/>
        <child link="caster_back_left_link"/>
        <origin xyz="-0.177 0.064 -0.004" rpy="-1.57 0 0"/>
      </joint>

      <link name="caster_back_left_link">
            <collision>
              <origin xyz="0 0.001 0" rpy="0 0 0"/>
              <geometry>
                <box size="0.030 0.009 0.020"/>
              </geometry>
            </collision>

            <inertial>
              <origin xyz="0 0 0" />
              <mass value="0.005" />
              <inertia ixx="0.001" ixy="0.0" ixz="0.0"
                      iyy="0.001" iyz="0.0"
                      izz="0.001" />
            </inertial>
      </link>
  -->
  <joint name="imu_joint" type="fixed">
    <parent link="base_link"/>
    <child link="imu_link"/>
    <origin xyz="0.0 0 0.068" rpy="0 0 0"/>
  </joint>

  <link name="imu_link"/>

  <joint name="scan_joint" type="fixed">
    <parent link="base_link"/>
    <child link="base_scan"/>
    <origin xyz="-0.064 0 0.122" rpy="0 0 0"/>
  </joint>

  <link name="base_scan">
    <visual>
      <origin xyz="0 0 0" rpy="0 0 0"/>
      <geometry>
        <mesh filename="package://turtlebot3_description/meshes/sensors/lds.stl" scale="0.001 0.001 0.001"/>
      </geometry>
      <material name="dark"/>
    </visual>
    <collision>
      <origin xyz="0.015 0 -0.0065" rpy="0 0 0"/>
      <geometry>
        <cylinder length="0.0315" radius="0.055"/>
      </geometry>
    </collision>
    <inertial>
      <mass value="0.114" />
      <origin xyz="0 0 0" />
      <inertia ixx="0.001" ixy="0.0" ixz="0.0"
               iyy="0.001" iyz="0.0"
               izz="0.001" />
    </inertial>
  </link>

<!-- ultrasom f -->
  <joint name="ultrasom_f_joint" type="fixed">
    <parent link="base_link"/>
    <child link="ultrasom_f_scan"/>
    <origin xyz="0.17 0 0.05" rpy="0 0 0"/>
  </joint>

  <link name="ultrasom_f_scan">
    <visual>
    
      <origin xyz="0 0 0" rpy="0 0 0"/>
      <geometry>
        <box size="0.05 0.05 0.02"/>
      </geometry>
      <material name="dark"/>
    </visual>
    <collision>
      <origin xyz="0.015 0 -0.0065" rpy="0 0 0"/>
      <!-- 1,558956 -->
      <geometry>
        <box size="0.05 0.05 0.02"/>
      </geometry>
    </collision>
    <inertial>
      <mass value="0.114" />
      <origin xyz="0 0 0" />
      <inertia ixx="0.001" ixy="0.0" ixz="0.0"
               iyy="0.001" iyz="0.0"
               izz="0.001" />
    </inertial>
  </link>
<!-- ultrasom f fim -->
<!-- ultrasom t -->
    <joint name="ultrasom_t_joint" type="fixed">
    <parent link="base_link"/>
    <child link="ultrasom_t_scan"/>
    <origin xyz="-0.15 0 0.05" rpy="0 0 3.133741"/>
  </joint>

  <link name="ultrasom_t_scan">
    <visual>
      <origin xyz="0 0 0" rpy="0 0 0"/>
      <geometry>
        <box size="0.05 0.05 0.02"/>
      </geometry>
      <material name="dark"/>
    </visual>
    <collision>
      <origin xyz="0.015 0 -0.0065" rpy="0 0 0"/>
      <geometry>
        <box size="0.05 0.05 0.02"/>
      </geometry>
    </collision>
    <inertial>
      <mass value="0.114" />
      <origin xyz="0 0 0" />
      <inertia ixx="0.001" ixy="0.0" ixz="0.0"
               iyy="0.001" iyz="0.0"
               izz="0.001" />
    </inertial>
  </link>
<!-- ultrasom t fim -->

<!-- ultrasom d -->
    <joint name="ultrasom_d_joint" type="fixed">
    <parent link="base_link"/>
    <child link="ultrasom_d_scan"/>
    <origin xyz="0 0.13 0.05" rpy="0 0 1.558956"/>
  </joint>

  <link name="ultrasom_d_scan">
    <visual>
      <origin xyz="0 0 0" rpy="0 0 0"/>
      <geometry>
        <box size="0.05 0.05 0.02"/>
      </geometry>
      <material name="dark"/>
    </visual>
    <collision>
      <origin xyz="0.015 0 -0.0065" rpy="0 0 0"/>
      <!-- 1,558956 -->
      <geometry>
        <box size="0.05 0.05 0.02"/>
      </geometry>
    </collision>
    <inertial>
      <mass value="0.114" />
      <origin xyz="0 0 0" />
      <inertia ixx="0.001" ixy="0.0" ixz="0.0"
               iyy="0.001" iyz="0.0"
               izz="0.001" />
    </inertial>
  </link>
<!-- ultrasom d fim -->
<!-- ultrasom e -->
    <joint name="ultrasom_e_joint" type="fixed">
    <parent link="base_link"/>
    <child link="ultrasom_e_scan"/>
    <origin xyz="0 -0.13 0.05" rpy="0 0 -1.569649"/>
  </joint>

  <link name="ultrasom_e_scan">
    <visual>
      <origin xyz="0 0 0" rpy="0 0 0"/>
      <!---1,569649 -->
      <geometry>
        <box size="0.05 0.05 0.02"/>
      </geometry>
      <material name="dark"/>
    </visual>
    <collision>
      <origin xyz="0.015 0 -0.0065" rpy="0 0 0"/>
      <geometry>
        <box size="0.05 0.05 0.02"/>
      </geometry>
    </collision>
    <inertial>
      <mass value="0.114" />
      <origin xyz="0 0 0" />
      <inertia ixx="0.001" ixy="0.0" ixz="0.0"
               iyy="0.001" iyz="0.0"
               izz="0.001" />
    </inertial>
  </link>
<!-- ultrasom e fim -->


  <joint name="camera_joint" type="fixed">
    <origin xyz="0.064 -0.065 0.094" rpy="0 0 0"/>
    <parent link="base_link"/>
    <child link="camera_link"/>
  </joint>

  <link name="camera_link">
    <visual>
    <origin xyz="0 0 0" rpy="1.57 0 1.57"/>
      <geometry>
        <mesh filename="package://turtlebot3_description/meshes/sensors/r200.dae" />
      </geometry>
    </visual>
    <collision>
      <origin xyz="0.003 0.065 0.007" rpy="0 0 0"/>
      <geometry>
        <box size="0.012 0.132 0.020"/>
      </geometry>
    </collision>
      <!-- This inertial field needs doesn't contain reliable data!! -->
      <!--   <inertial>
      <mass value="0.564" />
      <origin xyz="0 0 0" />
      <inertia ixx="0.003881243" ixy="0.0" ixz="0.0"
              iyy="0.000498940" iyz="0.0"
              izz="0.003879257" />
      </inertial>-->
  </link>

  <joint name="camera_rgb_joint" type="fixed">
    <origin xyz="${r200_cam_rgb_px} ${r200_cam_rgb_py} ${r200_cam_rgb_pz}" rpy="0 0 0"/>
    <parent link="camera_link"/>
    <child link="camera_rgb_frame"/>
  </joint>
  <link name="camera_rgb_frame"/>

  <joint name="camera_rgb_optical_joint" type="fixed">
    <origin xyz="0 0 0" rpy="-1.57 0 -1.57"/>
    <parent link="camera_rgb_frame"/>
    <child link="camera_rgb_optical_frame"/>
  </joint>

  <link name="camera_rgb_optical_frame"/>

  <joint name="camera_depth_joint" type="fixed">
    <origin xyz="${r200_cam_rgb_px} ${r200_cam_rgb_py + r200_cam_depth_offset} ${r200_cam_rgb_pz}" rpy="0 0 0"/>
    <parent link="camera_link"/>
    <child link="camera_depth_frame"/>
  </joint>

  <link name="camera_depth_frame"/>

  <joint name="camera_depth_optical_joint" type="fixed">
    <origin xyz="0 0 0" rpy="-1.57 0 -1.57"/>
    <parent link="camera_depth_frame"/>
    <child link="camera_depth_optical_frame"/>
  </joint>
  <link name="camera_depth_optical_frame"/>

</robot>
